<mujoco model="roarm_m3">
  <compiler angle="radian" meshdir="assets" autolimits="true"/>
  <option integrator="implicitfast" impratio="10"/>

  <default>
    <default class="roarm">
      <material specular="0.5" shininess="0.25"/>
      <joint type="hinge" armature="0.01" damping="0.1" axis="0 0 1"/>
      <motor ctrlrange="-30 30" forcerange="-30 30"/>
      <default class="visual">
        <geom type="mesh" contype="0" conaffinity="0" group="2"/>
      </default>
      <default class="collision">
        <geom type="mesh" group="3"/>
      </default>
      <site size="0.005" rgba="0.5 0.5 0.5 0.5" group="4"/>
    </default>
  </default>

  <asset>
    <material class="roarm" name="silver" rgba="0.75 0.75 0.75 1"/> 
    <mesh name="base_link_mesh" file="base_link.stl" scale="0.001 0.001 0.001"/>
    <mesh name="link1_mesh" file="link1.stl" scale="0.001 0.001 0.001"/>
    <mesh name="link2_mesh" file="link2.stl" scale="0.001 0.001 0.001"/>
    <mesh name="link3_mesh" file="link3.stl" scale="0.001 0.001 0.001"/>
    <mesh name="link4_mesh" file="link4.stl" scale="0.001 0.001 0.001"/>
    <mesh name="link5_mesh" file="link5.stl" scale="0.001 0.001 0.001"/>
    <mesh name="gripper_link_mesh" file="gripper_link.stl" scale="0.001 0.001 0.001"/>
  </asset>

  <worldbody>
    <light name="top" pos="0 0 1.5" mode="trackcom"/>

    <body name="base_link" pos="0.0 0.0 0.0701" quat="1 0 0 0" childclass="roarm">
      <inertial mass="0.2562183" pos="-0.0068 0 -0.03"
                fullinertia="0.00029211 0.00035719 0.000349421 0 0 0"/> <geom mesh="base_link_mesh" material="silver" class="visual"/>
      <geom mesh="base_link_mesh" class="collision"/>

      <body name="link1" pos="0 0 0" quat="1 0 0 0">
        <joint name="joint1" range="-3.1416 3.1416"/> <inertial mass="0.0729177" pos="0 0 0.037"
                  fullinertia="4.68465E-05 3.32107E-05 5.01023E-05 0 0 0"/>
        <geom mesh="link1_mesh" material="silver" class="visual"/>
        <geom mesh="link1_mesh" class="collision"/>

        <body name="link2" pos="0.0 0.0 0.051959" quat="0.5 0.5 -0.5 0.5">
          <joint name="joint2" range="-1.5708 1.5708"/> <inertial mass="0.0703216" pos="0.119 0.012247 -0.0001"
                    fullinertia="5.46501E-05 0.000423091 0.000404557 0 0 0"/>
          <geom mesh="link2_mesh" material="silver" class="visual"/>
          <geom mesh="link2_mesh" class="collision"/>

          <body name="link3" pos="0.236815 0.030002 0" quat="0.707107 0 0 0.707107">
             <joint name="joint3" range="-1 2.95"/> <inertial mass="0.021608" pos="-0.0015 -0.0765 0.00505"
                       fullinertia="6.37699E-05 3.67026E-06 6.28965E-05 0 0 0"/>
             <geom mesh="link3_mesh" material="silver" class="visual"/>
             <geom mesh="link3_mesh" class="collision"/>

             <body name="link4" pos="0.0 -0.144586 0" quat="1 0 0 0">
               <joint name="joint4" range="-1.5708 1.5708"/> <inertial mass="0.0099933" pos="-0.0015 -0.022 -0.00075"
                         fullinertia="4.53979E-06 3.78103E-06 5.60238E-06 0 0 0"/>
               <geom mesh="link4_mesh" material="silver" class="visual"/>
               <geom mesh="link4_mesh" class="collision"/>

               <body name="link5" pos="0.015147 -0.053653 0" quat="0.5 -0.5 0.5 0.5">
                 <joint name="joint5" range="-3.1416 3.1416"/> <inertial mass="0.0153928" pos="-0.0078 0 0.0595"
                           fullinertia="2.02869E-05 2.14427E-05 4.39495E-06 0 0 0"/>
                 <geom mesh="link5_mesh" material="silver" class="visual"/>
                 <geom mesh="link5_mesh" class="collision"/>

                 <body name="gripper_link" pos="0.00 0.018821 0.052035" quat="0.5 0.5 -0.5 0.5">
                   <joint name="joint6" range="0 1.5"/> <inertial mass="0.0028708" pos="0.027 0.0027 -0.018935"
                             fullinertia="5.23216E-07 1.82071E-06 1.60231E-06 0 0 0"/>
                   <geom mesh="gripper_link_mesh" material="silver" class="visual"/>
                   <geom mesh="gripper_link_mesh" class="collision"/>
                 </body> <site name="hand_tcp" pos="0 0 0.115428" quat="0.5 0.5 0.5 -0.5"/>

               </body> </body> </body> </body> </body> </body> </worldbody>

  <actuator>
    <motor class="roarm" name="actuator1" joint="joint1"/>
    <motor class="roarm" name="actuator2" joint="joint2"/>
    <motor class="roarm" name="actuator3" joint="joint3"/>
    <motor class="roarm" name="actuator4" joint="joint4"/>
    <motor class="roarm" name="actuator5" joint="joint5"/>
    <motor class="roarm" name="actuator6" joint="joint6" gear="1.0"/> </actuator>

  <keyframe>
    <key name="home" qpos="0 0 0 0 0 0" ctrl="0 0 0 0 0 0"/>
  </keyframe>

</mujoco>