<mujoco model="indy">
  <compiler angle="radian"/>
  <asset>
    <mesh name="Indy7_0" file="Indy7_0.stl"/>
    <mesh name="Indy7_1" file="Indy7_1.stl"/>
    <mesh name="Indy7_2" file="Indy7_2.stl"/>
    <mesh name="Indy7_3" file="Indy7_3.stl"/>
    <mesh name="Indy7_4" file="Indy7_4.stl"/>
    <mesh name="Indy7_5" file="Indy7_5.stl"/>
    <mesh name="Indy7_6" file="Indy7_6.stl"/>
  </asset>
  <worldbody>
    <geom type="mesh" rgba="0.894118 0.894118 0.894118 1" mesh="Indy7_0"/>
    <body name="link1" pos="0 0 0.0775">
      <inertial pos="-0.00023749 -0.0431031 0.132454" quat="0.982818 -0.181737 0.00632135 0.0316379" mass="11.4444" diaginertia="0.350666 0.346848 0.0179655"/>
      <joint name="joint0" pos="0 0 0" axis="0 0 1" range="-3.05433 3.05433"/>
      <geom type="mesh" rgba="0.894118 0.894118 0.894118 1" mesh="Indy7_1"/>
      <body name="link2" pos="0 -0.109 0.222" quat="0.5 0.5 0.5 -0.5">
        <inertial pos="-0.296167 2.254e-05 0.0448307" quat="0.519082 0.480113 0.480008 0.519266" mass="5.84767" diaginertia="0.722933 0.70435 0.0318886"/>
        <joint name="joint1" pos="0 0 0" axis="0 0 1" range="-3.05433 3.05433"/>
        <geom type="mesh" rgba="0.894118 0.894118 0.894118 1" mesh="Indy7_2"/>
        <body name="link3" pos="-0.45 0 -0.0305">
          <inertial pos="-0.16804 0.00021421 -0.0700038" quat="0.418393 0.563016 0.589764 0.400173" mass="2.68206" diaginertia="0.113644 0.111889 0.00450454"/>
          <joint name="joint2" pos="0 0 0" axis="0 0 1" range="-3.05433 3.05433"/>
          <geom type="mesh" rgba="0.894118 0.894118 0.894118 1" mesh="Indy7_3"/>
          <body name="link4" pos="-0.267 0 -0.075" quat="0.5 -0.5 -0.5 0.5">
            <inertial pos="-0.00026847 -0.0709844 0.0764913" quat="0.387066 0.920787 0.0444654 -0.0188077" mass="2.12987" diaginertia="0.0279949 0.0273562 0.00203069"/>
            <joint name="joint3" pos="0 0 0" axis="0 0 1" range="-3.05433 3.05433"/>
            <geom type="mesh" rgba="0.894118 0.894118 0.894118 1" mesh="Indy7_4"/>
            <body name="link5" pos="0 -0.114 0.083" quat="0.5 0.5 0.5 -0.5">
              <inertial pos="-0.0979623 -0.00023114 0.0644589" quat="0.638713 0.336607 0.365091 0.58775" mass="2.22412" diaginertia="0.0369879 0.0362556 0.00234029"/>
              <joint name="joint4" pos="0 0 0" axis="0 0 1" range="-3.05433 3.05433"/>
              <geom type="mesh" rgba="0.894118 0.894118 0.894118 1" mesh="Indy7_5"/>
              <body name="link6" pos="-0.168 0 0.069" quat="0.5 -0.5 -0.5 0.5">
                <inertial pos="8.147e-05 -0.00046556 0.030791" quat="0.690889 -0.00961156 0.00718031 0.722862" mass="0.382549" diaginertia="0.000797777 0.000789807 0.000583066"/>
                <joint name="joint5" pos="0 0 0" axis="0 0 1" range="-3.75246 3.75246"/>
                <geom type="mesh" rgba="0.894118 0.894118 0.894118 1" mesh="Indy7_6"/>
              </body>
            </body>
          </body>
        </body>
      </body>
    </body>
  </worldbody>
</mujoco>
